Seed set to 42
Seed set to 42
/raid/nvidiasys/env/lib/python3.8/site-packages/lightning_fabric/connector.py:565: `precision=16` is supported for historical reasons but its usage is discouraged. Please set your precision to 16-mixed instead!
Using 16bit Automatic Mixed Precision (AMP)
GPU available: True (cuda), used: True
TPU available: False, using: 0 TPU cores
IPU available: False, using: 0 IPUs
HPU available: False, using: 0 HPUs
/raid/nvidiasys/env/lib/python3.8/site-packages/pytorch_lightning/trainer/connectors/logger_connector/logger_connector.py:67: Starting from v1.9.0, `tensorboardX` has been removed as a dependency of the `pytorch_lightning` package, due to potential conflicts with other packages in the ML ecosystem. For this reason, `logger=True` will use `CSVLogger` as the default logger, unless the `tensorboard` or `tensorboardX` packages are found. Please `pip install lightning[extra]` or one of them to enable TensorBoard support by default
[rank: 0] Seed set to 42
Initializing distributed: GLOBAL_RANK: 0, MEMBER: 1/4
[rank: 2] Seed set to 42
[rank: 2] Seed set to 42
[rank: 1] Seed set to 42
[rank: 1] Seed set to 42
[rank: 3] Seed set to 42
[rank: 3] Seed set to 42
[rank: 2] Seed set to 42
Initializing distributed: GLOBAL_RANK: 2, MEMBER: 3/4
[rank: 1] Seed set to 42
Initializing distributed: GLOBAL_RANK: 1, MEMBER: 2/4
[rank: 3] Seed set to 42
Initializing distributed: GLOBAL_RANK: 3, MEMBER: 4/4
----------------------------------------------------------------------------------------------------
distributed_backend=nccl
All distributed processes registered. Starting with 4 processes
----------------------------------------------------------------------------------------------------

LOCAL_RANK: 3 - CUDA_VISIBLE_DEVICES: [0,1,2,3,4]
LOCAL_RANK: 2 - CUDA_VISIBLE_DEVICES: [0,1,2,3,4]
/raid/nvidiasys/env/lib/python3.8/site-packages/pytorch_lightning/callbacks/model_checkpoint.py:634: Checkpoint directory ../out2A3_MaP exists and is not empty.
LOCAL_RANK: 0 - CUDA_VISIBLE_DEVICES: [0,1,2,3,4]
LOCAL_RANK: 1 - CUDA_VISIBLE_DEVICES: [0,1,2,3,4]

  | Name      | Type               | Params
-------------------------------------------------
0 | model     | BPPReactivityModel | 8.1 M 
1 | criterion | MSELoss            | 0     
-------------------------------------------------
8.1 M     Trainable params
0         Non-trainable params
8.1 M     Total params
32.351    Total estimated model params size (MB)
Experiment type 2A3_MaP
<class 'models.BPPReactivityPredictorWithRNN'>
Sanity Checking: |          | 0/? [00:00<?, ?it/s]Experiment type 2A3_MaP
<class 'models.BPPReactivityPredictorWithRNN'>
Experiment type 2A3_MaP
<class 'models.BPPReactivityPredictorWithRNN'>
Experiment type 2A3_MaP
<class 'models.BPPReactivityPredictorWithRNN'>
Sanity Checking:   0%|          | 0/2 [00:00<?, ?it/s]Sanity Checking DataLoader 0:   0%|          | 0/2 [00:00<?, ?it/s]Sanity Checking DataLoader 0:  50%|█████     | 1/2 [00:01<00:01,  0.70it/s]Sanity Checking DataLoader 0: 100%|██████████| 2/2 [00:01<00:00,  1.40it/s]                                                                           Training: |          | 0/? [00:00<?, ?it/s]Training:   0%|          | 0/1418 [00:00<?, ?it/s]Epoch 0:   0%|          | 0/1418 [00:00<?, ?it/s] Epoch 0:   0%|          | 1/1418 [00:15<6:05:28,  0.06it/s]Epoch 0:   0%|          | 1/1418 [00:15<6:05:29,  0.06it/s, v_num=68]Epoch 0:   0%|          | 2/1418 [00:19<3:54:00,  0.10it/s, v_num=68]Epoch 0:   0%|          | 2/1418 [00:19<3:54:00,  0.10it/s, v_num=68]Epoch 0:   0%|          | 3/1418 [00:20<2:43:51,  0.14it/s, v_num=68]Epoch 0:   0%|          | 3/1418 [00:20<2:43:51,  0.14it/s, v_num=68]Epoch 0:   0%|          | 4/1418 [00:21<2:03:46,  0.19it/s, v_num=68]Epoch 0:   0%|          | 4/1418 [00:21<2:03:46,  0.19it/s, v_num=68]Epoch 0:   0%|          | 5/1418 [00:21<1:39:44,  0.24it/s, v_num=68]Epoch 0:   0%|          | 5/1418 [00:21<1:39:44,  0.24it/s, v_num=68]Epoch 0:   0%|          | 6/1418 [00:24<1:37:20,  0.24it/s, v_num=68]Epoch 0:   0%|          | 6/1418 [00:24<1:37:20,  0.24it/s, v_num=68]Epoch 0:   0%|          | 7/1418 [00:25<1:24:14,  0.28it/s, v_num=68]Epoch 0:   0%|          | 7/1418 [00:25<1:24:14,  0.28it/s, v_num=68]Epoch 0:   1%|          | 8/1418 [00:27<1:21:23,  0.29it/s, v_num=68]Epoch 0:   1%|          | 8/1418 [00:27<1:21:23,  0.29it/s, v_num=68]Epoch 0:   1%|          | 9/1418 [00:29<1:15:44,  0.31it/s, v_num=68]Epoch 0:   1%|          | 9/1418 [00:29<1:15:44,  0.31it/s, v_num=68]Epoch 0:   1%|          | 10/1418 [00:29<1:08:30,  0.34it/s, v_num=68]Epoch 0:   1%|          | 10/1418 [00:29<1:08:30,  0.34it/s, v_num=68]Epoch 0:   1%|          | 11/1418 [00:29<1:03:46,  0.37it/s, v_num=68]Epoch 0:   1%|          | 11/1418 [00:29<1:03:46,  0.37it/s, v_num=68]Epoch 0:   1%|          | 12/1418 [00:31<1:00:49,  0.39it/s, v_num=68]Epoch 0:   1%|          | 12/1418 [00:31<1:00:49,  0.39it/s, v_num=68]Exception in thread Thread-3:
Traceback (most recent call last):
  File "/usr/lib/python3.8/threading.py", line 932, in _bootstrap_inner
    self.run()
  File "/usr/lib/python3.8/threading.py", line 870, in run
    self._target(*self._args, **self._kwargs)
  File "/raid/nvidiasys/env/lib/python3.8/site-packages/torch/utils/data/_utils/pin_memory.py", line 54, in _pin_memory_loop
    do_one_step()
  File "/raid/nvidiasys/env/lib/python3.8/site-packages/torch/utils/data/_utils/pin_memory.py", line 31, in do_one_step
    r = in_queue.get(timeout=MP_STATUS_CHECK_INTERVAL)
  File "/usr/lib/python3.8/multiprocessing/queues.py", line 116, in get
    return _ForkingPickler.loads(res)
  File "/raid/nvidiasys/env/lib/python3.8/site-packages/torch/multiprocessing/reductions.py", line 355, in rebuild_storage_fd
    fd = df.detach()
  File "/usr/lib/python3.8/multiprocessing/resource_sharer.py", line 57, in detach
    with _resource_sharer.get_connection(self._id) as conn:
  File "/usr/lib/python3.8/multiprocessing/resource_sharer.py", line 87, in get_connection
    c = Client(address, authkey=process.current_process().authkey)
  File "/usr/lib/python3.8/multiprocessing/connection.py", line 502, in Client
    c = SocketClient(address)
  File "/usr/lib/python3.8/multiprocessing/connection.py", line 630, in SocketClient
    s.connect(address)
FileNotFoundError: [Errno 2] No such file or directory
Seed set to 42
Seed set to 42
/raid/nvidiasys/env/lib/python3.8/site-packages/lightning_fabric/connector.py:565: `precision=16` is supported for historical reasons but its usage is discouraged. Please set your precision to 16-mixed instead!
Using 16bit Automatic Mixed Precision (AMP)
GPU available: True (cuda), used: True
TPU available: False, using: 0 TPU cores
IPU available: False, using: 0 IPUs
HPU available: False, using: 0 HPUs
/raid/nvidiasys/env/lib/python3.8/site-packages/pytorch_lightning/trainer/connectors/logger_connector/logger_connector.py:67: Starting from v1.9.0, `tensorboardX` has been removed as a dependency of the `pytorch_lightning` package, due to potential conflicts with other packages in the ML ecosystem. For this reason, `logger=True` will use `CSVLogger` as the default logger, unless the `tensorboard` or `tensorboardX` packages are found. Please `pip install lightning[extra]` or one of them to enable TensorBoard support by default
[rank: 0] Seed set to 42
Initializing distributed: GLOBAL_RANK: 0, MEMBER: 1/4
[rank: 2] Seed set to 42
[rank: 2] Seed set to 42
[rank: 1] Seed set to 42
[rank: 1] Seed set to 42
[rank: 3] Seed set to 42
[rank: 3] Seed set to 42
[rank: 1] Seed set to 42
Initializing distributed: GLOBAL_RANK: 1, MEMBER: 2/4
[rank: 2] Seed set to 42
Initializing distributed: GLOBAL_RANK: 2, MEMBER: 3/4
[rank: 3] Seed set to 42
Initializing distributed: GLOBAL_RANK: 3, MEMBER: 4/4
----------------------------------------------------------------------------------------------------
distributed_backend=nccl
All distributed processes registered. Starting with 4 processes
----------------------------------------------------------------------------------------------------

LOCAL_RANK: 1 - CUDA_VISIBLE_DEVICES: [0,1,2,3,4]
/raid/nvidiasys/env/lib/python3.8/site-packages/pytorch_lightning/callbacks/model_checkpoint.py:634: Checkpoint directory ../out2A3_MaP exists and is not empty.
LOCAL_RANK: 0 - CUDA_VISIBLE_DEVICES: [0,1,2,3,4]
LOCAL_RANK: 2 - CUDA_VISIBLE_DEVICES: [0,1,2,3,4]
LOCAL_RANK: 3 - CUDA_VISIBLE_DEVICES: [0,1,2,3,4]

  | Name      | Type               | Params
-------------------------------------------------
0 | model     | BPPReactivityModel | 8.1 M 
1 | criterion | MSELoss            | 0     
-------------------------------------------------
8.1 M     Trainable params
0         Non-trainable params
8.1 M     Total params
32.351    Total estimated model params size (MB)
Experiment type 2A3_MaP
<class 'models.BPPReactivityPredictorWithRNN'>
Experiment type 2A3_MaP
<class 'models.BPPReactivityPredictorWithRNN'>
Experiment type 2A3_MaP
<class 'models.BPPReactivityPredictorWithRNN'>
Experiment type 2A3_MaP
<class 'models.BPPReactivityPredictorWithRNN'>
Exception in thread Thread-2:
Traceback (most recent call last):
  File "/usr/lib/python3.8/threading.py", line 932, in _bootstrap_inner
    self.run()
  File "/usr/lib/python3.8/threading.py", line 870, in run
    self._target(*self._args, **self._kwargs)
  File "/raid/nvidiasys/env/lib/python3.8/site-packages/torch/utils/data/_utils/pin_memory.py", line 54, in _pin_memory_loop
    do_one_step()
  File "/raid/nvidiasys/env/lib/python3.8/site-packages/torch/utils/data/_utils/pin_memory.py", line 31, in do_one_step
    r = in_queue.get(timeout=MP_STATUS_CHECK_INTERVAL)
  File "/usr/lib/python3.8/multiprocessing/queues.py", line 116, in get
    return _ForkingPickler.loads(res)
  File "/raid/nvidiasys/env/lib/python3.8/site-packages/torch/multiprocessing/reductions.py", line 355, in rebuild_storage_fd
    fd = df.detach()
  File "/usr/lib/python3.8/multiprocessing/resource_sharer.py", line 57, in detach
    with _resource_sharer.get_connection(self._id) as conn:
  File "/usr/lib/python3.8/multiprocessing/resource_sharer.py", line 87, in get_connection
    c = Client(address, authkey=process.current_process().authkey)
  File "/usr/lib/python3.8/multiprocessing/connection.py", line 502, in Client
    c = SocketClient(address)
  File "/usr/lib/python3.8/multiprocessing/connection.py", line 630, in SocketClient
    s.connect(address)
FileNotFoundError: [Errno 2] No such file or directory
Exception in thread Thread-1:
Traceback (most recent call last):
  File "/usr/lib/python3.8/threading.py", line 932, in _bootstrap_inner
    self.run()
  File "/usr/lib/python3.8/threading.py", line 870, in run
    self._target(*self._args, **self._kwargs)
  File "/raid/nvidiasys/env/lib/python3.8/site-packages/torch/utils/data/_utils/pin_memory.py", line 54, in _pin_memory_loop
    do_one_step()
  File "/raid/nvidiasys/env/lib/python3.8/site-packages/torch/utils/data/_utils/pin_memory.py", line 31, in do_one_step
    r = in_queue.get(timeout=MP_STATUS_CHECK_INTERVAL)
  File "/usr/lib/python3.8/multiprocessing/queues.py", line 116, in get
    return _ForkingPickler.loads(res)
  File "/raid/nvidiasys/env/lib/python3.8/site-packages/torch/multiprocessing/reductions.py", line 355, in rebuild_storage_fd
    fd = df.detach()
  File "/usr/lib/python3.8/multiprocessing/resource_sharer.py", line 57, in detach
    with _resource_sharer.get_connection(self._id) as conn:
  File "/usr/lib/python3.8/multiprocessing/resource_sharer.py", line 87, in get_connection
    c = Client(address, authkey=process.current_process().authkey)
  File "/usr/lib/python3.8/multiprocessing/connection.py", line 502, in Client
    c = SocketClient(address)
  File "/usr/lib/python3.8/multiprocessing/connection.py", line 630, in SocketClient
    s.connect(address)
FileNotFoundError: [Errno 2] No such file or directory
/raid/nvidiasys/env/lib/python3.8/site-packages/pytorch_lightning/trainer/call.py:54: Detected KeyboardInterrupt, attempting graceful shutdown...
Exception in thread Thread-1:
Traceback (most recent call last):
  File "/usr/lib/python3.8/threading.py", line 932, in _bootstrap_inner
    self.run()
  File "/usr/lib/python3.8/threading.py", line 870, in run
    self._target(*self._args, **self._kwargs)
  File "/raid/nvidiasys/env/lib/python3.8/site-packages/torch/utils/data/_utils/pin_memory.py", line 54, in _pin_memory_loop
    do_one_step()
  File "/raid/nvidiasys/env/lib/python3.8/site-packages/torch/utils/data/_utils/pin_memory.py", line 31, in do_one_step
    r = in_queue.get(timeout=MP_STATUS_CHECK_INTERVAL)
  File "/usr/lib/python3.8/multiprocessing/queues.py", line 116, in get
    return _ForkingPickler.loads(res)
  File "/raid/nvidiasys/env/lib/python3.8/site-packages/torch/multiprocessing/reductions.py", line 355, in rebuild_storage_fd
    fd = df.detach()
  File "/usr/lib/python3.8/multiprocessing/resource_sharer.py", line 57, in detach
    with _resource_sharer.get_connection(self._id) as conn:
  File "/usr/lib/python3.8/multiprocessing/resource_sharer.py", line 87, in get_connection
    c = Client(address, authkey=process.current_process().authkey)
  File "/usr/lib/python3.8/multiprocessing/connection.py", line 502, in Client
    c = SocketClient(address)
  File "/usr/lib/python3.8/multiprocessing/connection.py", line 630, in SocketClient
    s.connect(address)
FileNotFoundError: [Errno 2] No such file or directory
Exception in thread Thread-2:
Traceback (most recent call last):
  File "/usr/lib/python3.8/threading.py", line 932, in _bootstrap_inner
    self.run()
  File "/usr/lib/python3.8/threading.py", line 870, in run
    self._target(*self._args, **self._kwargs)
  File "/raid/nvidiasys/env/lib/python3.8/site-packages/torch/utils/data/_utils/pin_memory.py", line 54, in _pin_memory_loop
    do_one_step()
  File "/raid/nvidiasys/env/lib/python3.8/site-packages/torch/utils/data/_utils/pin_memory.py", line 31, in do_one_step
    r = in_queue.get(timeout=MP_STATUS_CHECK_INTERVAL)
  File "/usr/lib/python3.8/multiprocessing/queues.py", line 116, in get
    return _ForkingPickler.loads(res)
  File "/raid/nvidiasys/env/lib/python3.8/site-packages/torch/multiprocessing/reductions.py", line 355, in rebuild_storage_fd
    fd = df.detach()
  File "/usr/lib/python3.8/multiprocessing/resource_sharer.py", line 57, in detach
    with _resource_sharer.get_connection(self._id) as conn:
  File "/usr/lib/python3.8/multiprocessing/resource_sharer.py", line 87, in get_connection
    c = Client(address, authkey=process.current_process().authkey)
  File "/usr/lib/python3.8/multiprocessing/connection.py", line 502, in Client
    c = SocketClient(address)
  File "/usr/lib/python3.8/multiprocessing/connection.py", line 630, in SocketClient
    s.connect(address)
FileNotFoundError: [Errno 2] No such file or directory
Exception in thread Thread-1:
Traceback (most recent call last):
  File "/usr/lib/python3.8/threading.py", line 932, in _bootstrap_inner
    self.run()
  File "/usr/lib/python3.8/threading.py", line 870, in run
    self._target(*self._args, **self._kwargs)
  File "/raid/nvidiasys/env/lib/python3.8/site-packages/torch/utils/data/_utils/pin_memory.py", line 54, in _pin_memory_loop
    do_one_step()
  File "/raid/nvidiasys/env/lib/python3.8/site-packages/torch/utils/data/_utils/pin_memory.py", line 31, in do_one_step
    r = in_queue.get(timeout=MP_STATUS_CHECK_INTERVAL)
  File "/usr/lib/python3.8/multiprocessing/queues.py", line 116, in get
    return _ForkingPickler.loads(res)
  File "/raid/nvidiasys/env/lib/python3.8/site-packages/torch/multiprocessing/reductions.py", line 355, in rebuild_storage_fd
    fd = df.detach()
  File "/usr/lib/python3.8/multiprocessing/resource_sharer.py", line 57, in detach
    with _resource_sharer.get_connection(self._id) as conn:
  File "/usr/lib/python3.8/multiprocessing/resource_sharer.py", line 87, in get_connection
    c = Client(address, authkey=process.current_process().authkey)
  File "/usr/lib/python3.8/multiprocessing/connection.py", line 502, in Client
    c = SocketClient(address)
  File "/usr/lib/python3.8/multiprocessing/connection.py", line 630, in SocketClient
    s.connect(address)
FileNotFoundError: [Errno 2] No such file or directory
Exception in thread Thread-3:
Traceback (most recent call last):
  File "/usr/lib/python3.8/threading.py", line 932, in _bootstrap_inner
    self.run()
  File "/usr/lib/python3.8/threading.py", line 870, in run
    self._target(*self._args, **self._kwargs)
  File "/raid/nvidiasys/env/lib/python3.8/site-packages/torch/utils/data/_utils/pin_memory.py", line 54, in _pin_memory_loop
    do_one_step()
  File "/raid/nvidiasys/env/lib/python3.8/site-packages/torch/utils/data/_utils/pin_memory.py", line 31, in do_one_step
    r = in_queue.get(timeout=MP_STATUS_CHECK_INTERVAL)
  File "/usr/lib/python3.8/multiprocessing/queues.py", line 116, in get
    return _ForkingPickler.loads(res)
  File "/raid/nvidiasys/env/lib/python3.8/site-packages/torch/multiprocessing/reductions.py", line 355, in rebuild_storage_fd
    fd = df.detach()
  File "/usr/lib/python3.8/multiprocessing/resource_sharer.py", line 57, in detach
    with _resource_sharer.get_connection(self._id) as conn:
  File "/usr/lib/python3.8/multiprocessing/resource_sharer.py", line 87, in get_connection
    c = Client(address, authkey=process.current_process().authkey)
  File "/usr/lib/python3.8/multiprocessing/connection.py", line 502, in Client
    c = SocketClient(address)
  File "/usr/lib/python3.8/multiprocessing/connection.py", line 630, in SocketClient
    s.connect(address)
FileNotFoundError: [Errno 2] No such file or directory
Exception in thread Thread-2:
Traceback (most recent call last):
  File "/usr/lib/python3.8/threading.py", line 932, in _bootstrap_inner
    self.run()
  File "/usr/lib/python3.8/threading.py", line 870, in run
    self._target(*self._args, **self._kwargs)
  File "/raid/nvidiasys/env/lib/python3.8/site-packages/torch/utils/data/_utils/pin_memory.py", line 54, in _pin_memory_loop
    do_one_step()
  File "/raid/nvidiasys/env/lib/python3.8/site-packages/torch/utils/data/_utils/pin_memory.py", line 31, in do_one_step
    r = in_queue.get(timeout=MP_STATUS_CHECK_INTERVAL)
  File "/usr/lib/python3.8/multiprocessing/queues.py", line 116, in get
    return _ForkingPickler.loads(res)
  File "/raid/nvidiasys/env/lib/python3.8/site-packages/torch/multiprocessing/reductions.py", line 355, in rebuild_storage_fd
    fd = df.detach()
  File "/usr/lib/python3.8/multiprocessing/resource_sharer.py", line 57, in detach
    with _resource_sharer.get_connection(self._id) as conn:
  File "/usr/lib/python3.8/multiprocessing/resource_sharer.py", line 87, in get_connection
    c = Client(address, authkey=process.current_process().authkey)
  File "/usr/lib/python3.8/multiprocessing/connection.py", line 502, in Client
    c = SocketClient(address)
  File "/usr/lib/python3.8/multiprocessing/connection.py", line 630, in SocketClient
    s.connect(address)
FileNotFoundError: [Errno 2] No such file or directory
Exception in thread Thread-2:
Traceback (most recent call last):
  File "/usr/lib/python3.8/threading.py", line 932, in _bootstrap_inner
    self.run()
  File "/usr/lib/python3.8/threading.py", line 870, in run
    self._target(*self._args, **self._kwargs)
  File "/raid/nvidiasys/env/lib/python3.8/site-packages/torch/utils/data/_utils/pin_memory.py", line 54, in _pin_memory_loop
    do_one_step()
  File "/raid/nvidiasys/env/lib/python3.8/site-packages/torch/utils/data/_utils/pin_memory.py", line 31, in do_one_step
    r = in_queue.get(timeout=MP_STATUS_CHECK_INTERVAL)
  File "/usr/lib/python3.8/multiprocessing/queues.py", line 116, in get
    return _ForkingPickler.loads(res)
  File "/raid/nvidiasys/env/lib/python3.8/site-packages/torch/multiprocessing/reductions.py", line 355, in rebuild_storage_fd
    fd = df.detach()
  File "/usr/lib/python3.8/multiprocessing/resource_sharer.py", line 57, in detach
    with _resource_sharer.get_connection(self._id) as conn:
  File "/usr/lib/python3.8/multiprocessing/resource_sharer.py", line 87, in get_connection
    c = Client(address, authkey=process.current_process().authkey)
  File "/usr/lib/python3.8/multiprocessing/connection.py", line 502, in Client
    c = SocketClient(address)
  File "/usr/lib/python3.8/multiprocessing/connection.py", line 630, in SocketClient
    s.connect(address)
FileNotFoundError: [Errno 2] No such file or directory
Seed set to 42
Seed set to 42
/raid/nvidiasys/env/lib/python3.8/site-packages/lightning_fabric/connector.py:565: `precision=16` is supported for historical reasons but its usage is discouraged. Please set your precision to 16-mixed instead!
Using 16bit Automatic Mixed Precision (AMP)
GPU available: True (cuda), used: True
TPU available: False, using: 0 TPU cores
IPU available: False, using: 0 IPUs
HPU available: False, using: 0 HPUs
[rank: 0] Seed set to 42
Initializing distributed: GLOBAL_RANK: 0, MEMBER: 1/4
[rank: 1] Seed set to 42
[rank: 1] Seed set to 42
[rank: 2] Seed set to 42
[rank: 2] Seed set to 42
[rank: 3] Seed set to 42
[rank: 3] Seed set to 42
[rank: 1] Seed set to 42
Initializing distributed: GLOBAL_RANK: 1, MEMBER: 2/4
[rank: 2] Seed set to 42
Initializing distributed: GLOBAL_RANK: 2, MEMBER: 3/4
[rank: 3] Seed set to 42
Initializing distributed: GLOBAL_RANK: 3, MEMBER: 4/4
----------------------------------------------------------------------------------------------------
distributed_backend=nccl
All distributed processes registered. Starting with 4 processes
----------------------------------------------------------------------------------------------------

LOCAL_RANK: 3 - CUDA_VISIBLE_DEVICES: [0,1,2,3,4]
LOCAL_RANK: 2 - CUDA_VISIBLE_DEVICES: [0,1,2,3,4]
/raid/nvidiasys/env/lib/python3.8/site-packages/pytorch_lightning/callbacks/model_checkpoint.py:634: Checkpoint directory ../out2A3_MaP exists and is not empty.
LOCAL_RANK: 0 - CUDA_VISIBLE_DEVICES: [0,1,2,3,4]
LOCAL_RANK: 1 - CUDA_VISIBLE_DEVICES: [0,1,2,3,4]

  | Name      | Type               | Params
-------------------------------------------------
0 | model     | BPPReactivityModel | 8.1 M 
1 | criterion | MSELoss            | 0     
-------------------------------------------------
8.1 M     Trainable params
0         Non-trainable params
8.1 M     Total params
32.351    Total estimated model params size (MB)
Experiment type 2A3_MaP
<class 'models.BPPReactivityPredictorWithRNN'>
Experiment type 2A3_MaP
<class 'models.BPPReactivityPredictorWithRNN'>
Experiment type 2A3_MaP
<class 'models.BPPReactivityPredictorWithRNN'>
Experiment type 2A3_MaP
<class 'models.BPPReactivityPredictorWithRNN'>
`Trainer.fit` stopped: `max_epochs=25` reached.
Seed set to 42
Seed set to 42
/raid/nvidiasys/env/lib/python3.8/site-packages/lightning_fabric/connector.py:565: `precision=16` is supported for historical reasons but its usage is discouraged. Please set your precision to 16-mixed instead!
Using 16bit Automatic Mixed Precision (AMP)
GPU available: True (cuda), used: True
TPU available: False, using: 0 TPU cores
IPU available: False, using: 0 IPUs
HPU available: False, using: 0 HPUs
[rank: 0] Seed set to 42
Initializing distributed: GLOBAL_RANK: 0, MEMBER: 1/4
[rank: 2] Seed set to 42
[rank: 2] Seed set to 42
[rank: 1] Seed set to 42
[rank: 1] Seed set to 42
[rank: 3] Seed set to 42
[rank: 3] Seed set to 42
[rank: 1] Seed set to 42
Initializing distributed: GLOBAL_RANK: 1, MEMBER: 2/4
[rank: 2] Seed set to 42
Initializing distributed: GLOBAL_RANK: 2, MEMBER: 3/4
[rank: 3] Seed set to 42
Initializing distributed: GLOBAL_RANK: 3, MEMBER: 4/4
----------------------------------------------------------------------------------------------------
distributed_backend=nccl
All distributed processes registered. Starting with 4 processes
----------------------------------------------------------------------------------------------------

LOCAL_RANK: 3 - CUDA_VISIBLE_DEVICES: [0,1,2,3,4]
LOCAL_RANK: 2 - CUDA_VISIBLE_DEVICES: [0,1,2,3,4]
/raid/nvidiasys/env/lib/python3.8/site-packages/pytorch_lightning/callbacks/model_checkpoint.py:634: Checkpoint directory ../outDMS_MaP exists and is not empty.
LOCAL_RANK: 0 - CUDA_VISIBLE_DEVICES: [0,1,2,3,4]
LOCAL_RANK: 1 - CUDA_VISIBLE_DEVICES: [0,1,2,3,4]

  | Name      | Type               | Params
-------------------------------------------------
0 | model     | BPPReactivityModel | 8.1 M 
1 | criterion | MSELoss            | 0     
-------------------------------------------------
8.1 M     Trainable params
0         Non-trainable params
8.1 M     Total params
32.351    Total estimated model params size (MB)
Experiment type DMS_MaP
<class 'models.BPPReactivityPredictorWithRNN'>
Experiment type DMS_MaP
<class 'models.BPPReactivityPredictorWithRNN'>
Experiment type DMS_MaP
<class 'models.BPPReactivityPredictorWithRNN'>
Experiment type DMS_MaP
<class 'models.BPPReactivityPredictorWithRNN'>
`Trainer.fit` stopped: `max_epochs=25` reached.
